[2024-10-13T23:05:32.963+0000] {local_task_job_runner.py:123} INFO - ::group::Pre task execution logs
[2024-10-13T23:05:32.995+0000] {taskinstance.py:2612} INFO - Dependencies all met for dep_context=non-requeueable deps ti=<TaskInstance: ml_workflow_jhayr.load_data manual__2024-10-13T23:04:20.859635+00:00 [queued]>
[2024-10-13T23:05:33.053+0000] {taskinstance.py:2612} INFO - Dependencies all met for dep_context=requeueable deps ti=<TaskInstance: ml_workflow_jhayr.load_data manual__2024-10-13T23:04:20.859635+00:00 [queued]>
[2024-10-13T23:05:33.061+0000] {taskinstance.py:2865} INFO - Starting attempt 2 of 2
[2024-10-13T23:05:33.088+0000] {taskinstance.py:2888} INFO - Executing <Task(PythonOperator): load_data> on 2024-10-13 23:04:20.859635+00:00
[2024-10-13T23:05:33.102+0000] {warnings.py:112} WARNING - /home/***/.local/lib/python3.12/site-packages/***/task/task_runner/standard_task_runner.py:70: DeprecationWarning: This process (pid=106) is multi-threaded, use of fork() may lead to deadlocks in the child.
  pid = os.fork()

[2024-10-13T23:05:33.105+0000] {standard_task_runner.py:72} INFO - Started process 119 to run task
[2024-10-13T23:05:33.105+0000] {standard_task_runner.py:104} INFO - Running: ['***', 'tasks', 'run', 'ml_workflow_jhayr', 'load_data', 'manual__2024-10-13T23:04:20.859635+00:00', '--job-id', '24', '--raw', '--subdir', 'DAGS_FOLDER/pipeline.py', '--cfg-path', '/tmp/tmpklgirpoy']
[2024-10-13T23:05:33.107+0000] {standard_task_runner.py:105} INFO - Job 24: Subtask load_data
[2024-10-13T23:05:33.180+0000] {task_command.py:467} INFO - Running <TaskInstance: ml_workflow_jhayr.load_data manual__2024-10-13T23:04:20.859635+00:00 [running]> on host d8275d2c7247
[2024-10-13T23:05:33.325+0000] {taskinstance.py:3131} INFO - Exporting env vars: AIRFLOW_CTX_DAG_OWNER='***' AIRFLOW_CTX_DAG_ID='ml_workflow_jhayr' AIRFLOW_CTX_TASK_ID='load_data' AIRFLOW_CTX_EXECUTION_DATE='2024-10-13T23:04:20.859635+00:00' AIRFLOW_CTX_TRY_NUMBER='2' AIRFLOW_CTX_DAG_RUN_ID='manual__2024-10-13T23:04:20.859635+00:00'
[2024-10-13T23:05:33.328+0000] {logging_mixin.py:190} INFO - Task instance is in running state
[2024-10-13T23:05:33.329+0000] {logging_mixin.py:190} INFO -  Previous state of the Task instance: queued
[2024-10-13T23:05:33.330+0000] {logging_mixin.py:190} INFO - Current task name:load_data state:running start_date:2024-10-13 23:05:33.038227+00:00
[2024-10-13T23:05:33.331+0000] {logging_mixin.py:190} INFO - Dag name:ml_workflow_jhayr and current dag run status:running
[2024-10-13T23:05:33.332+0000] {taskinstance.py:731} INFO - ::endgroup::
[2024-10-13T23:05:33.339+0000] {taskinstance.py:3310} ERROR - Task failed with exception
Traceback (most recent call last):
  File "/home/airflow/.local/lib/python3.12/site-packages/airflow/models/taskinstance.py", line 767, in _execute_task
    result = _execute_callable(context=context, **execute_callable_kwargs)
             ^^^^^^^^^^^^^^^^^^^^^^^^^^^^^^^^^^^^^^^^^^^^^^^^^^^^^^^^^^^^^
  File "/home/airflow/.local/lib/python3.12/site-packages/airflow/models/taskinstance.py", line 733, in _execute_callable
    return ExecutionCallableRunner(
           ^^^^^^^^^^^^^^^^^^^^^^^^
  File "/home/airflow/.local/lib/python3.12/site-packages/airflow/utils/operator_helpers.py", line 252, in run
    return self.func(*args, **kwargs)
           ^^^^^^^^^^^^^^^^^^^^^^^^^^
  File "/home/airflow/.local/lib/python3.12/site-packages/airflow/models/baseoperator.py", line 406, in wrapper
    return func(self, *args, **kwargs)
           ^^^^^^^^^^^^^^^^^^^^^^^^^^^
  File "/home/airflow/.local/lib/python3.12/site-packages/airflow/operators/python.py", line 238, in execute
    return_value = self.execute_callable()
                   ^^^^^^^^^^^^^^^^^^^^^^^
  File "/home/airflow/.local/lib/python3.12/site-packages/airflow/operators/python.py", line 256, in execute_callable
    return runner.run(*self.op_args, **self.op_kwargs)
           ^^^^^^^^^^^^^^^^^^^^^^^^^^^^^^^^^^^^^^^^^^^
  File "/home/airflow/.local/lib/python3.12/site-packages/airflow/utils/operator_helpers.py", line 252, in run
    return self.func(*args, **kwargs)
           ^^^^^^^^^^^^^^^^^^^^^^^^^^
  File "/opt/airflow/dags/pipeline.py", line 44, in load_data
    df = pd.read_csv(data_path)
         ^^^^^^^^^^^^^^^^^^^^^^
  File "/home/airflow/.local/lib/python3.12/site-packages/pandas/io/parsers/readers.py", line 1026, in read_csv
    return _read(filepath_or_buffer, kwds)
           ^^^^^^^^^^^^^^^^^^^^^^^^^^^^^^^
  File "/home/airflow/.local/lib/python3.12/site-packages/pandas/io/parsers/readers.py", line 620, in _read
    parser = TextFileReader(filepath_or_buffer, **kwds)
             ^^^^^^^^^^^^^^^^^^^^^^^^^^^^^^^^^^^^^^^^^^
  File "/home/airflow/.local/lib/python3.12/site-packages/pandas/io/parsers/readers.py", line 1620, in __init__
    self._engine = self._make_engine(f, self.engine)
                   ^^^^^^^^^^^^^^^^^^^^^^^^^^^^^^^^^
  File "/home/airflow/.local/lib/python3.12/site-packages/pandas/io/parsers/readers.py", line 1880, in _make_engine
    self.handles = get_handle(
                   ^^^^^^^^^^^
  File "/home/airflow/.local/lib/python3.12/site-packages/pandas/io/common.py", line 873, in get_handle
    handle = open(
             ^^^^^
FileNotFoundError: [Errno 2] No such file or directory: 'C:/Users/LENOVO/Documents/machine_learning_engineer/DMC/practica1/dags/data/train.csv'
[2024-10-13T23:05:33.376+0000] {logging_mixin.py:190} INFO - Task instance in failure state
[2024-10-13T23:05:33.377+0000] {logging_mixin.py:190} INFO - Task start:2024-10-13 23:05:33.038227+00:00 end:2024-10-13 23:05:33.375021+00:00 duration:0.336794
[2024-10-13T23:05:33.379+0000] {logging_mixin.py:190} INFO - Task:<Task(PythonOperator): load_data> dag:<DAG: ml_workflow_jhayr> dagrun:<DagRun ml_workflow_jhayr @ 2024-10-13 23:04:20.859635+00:00: manual__2024-10-13T23:04:20.859635+00:00, state:running, queued_at: 2024-10-13 23:04:20.915822+00:00. externally triggered: True>
[2024-10-13T23:05:33.380+0000] {logging_mixin.py:190} INFO - Failure caused by [Errno 2] No such file or directory: 'C:/Users/LENOVO/Documents/machine_learning_engineer/DMC/practica1/dags/data/train.csv'
[2024-10-13T23:05:33.383+0000] {taskinstance.py:1225} INFO - Marking task as FAILED. dag_id=ml_workflow_jhayr, task_id=load_data, run_id=manual__2024-10-13T23:04:20.859635+00:00, execution_date=20241013T230420, start_date=20241013T230533, end_date=20241013T230533
[2024-10-13T23:05:33.416+0000] {taskinstance.py:340} INFO - ::group::Post task execution logs
[2024-10-13T23:05:33.418+0000] {standard_task_runner.py:124} ERROR - Failed to execute job 24 for task load_data ([Errno 2] No such file or directory: 'C:/Users/LENOVO/Documents/machine_learning_engineer/DMC/practica1/dags/data/train.csv'; 119)
Traceback (most recent call last):
  File "/home/airflow/.local/lib/python3.12/site-packages/airflow/task/task_runner/standard_task_runner.py", line 117, in _start_by_fork
    ret = args.func(args, dag=self.dag)
          ^^^^^^^^^^^^^^^^^^^^^^^^^^^^^
  File "/home/airflow/.local/lib/python3.12/site-packages/airflow/cli/cli_config.py", line 49, in command
    return func(*args, **kwargs)
           ^^^^^^^^^^^^^^^^^^^^^
  File "/home/airflow/.local/lib/python3.12/site-packages/airflow/utils/cli.py", line 115, in wrapper
    return f(*args, **kwargs)
           ^^^^^^^^^^^^^^^^^^
  File "/home/airflow/.local/lib/python3.12/site-packages/airflow/cli/commands/task_command.py", line 483, in task_run
    task_return_code = _run_task_by_selected_method(args, _dag, ti)
                       ^^^^^^^^^^^^^^^^^^^^^^^^^^^^^^^^^^^^^^^^^^^^
  File "/home/airflow/.local/lib/python3.12/site-packages/airflow/cli/commands/task_command.py", line 256, in _run_task_by_selected_method
    return _run_raw_task(args, ti)
           ^^^^^^^^^^^^^^^^^^^^^^^
  File "/home/airflow/.local/lib/python3.12/site-packages/airflow/cli/commands/task_command.py", line 341, in _run_raw_task
    return ti._run_raw_task(
           ^^^^^^^^^^^^^^^^^
  File "/home/airflow/.local/lib/python3.12/site-packages/airflow/utils/session.py", line 97, in wrapper
    return func(*args, session=session, **kwargs)
           ^^^^^^^^^^^^^^^^^^^^^^^^^^^^^^^^^^^^^^
  File "/home/airflow/.local/lib/python3.12/site-packages/airflow/models/taskinstance.py", line 3004, in _run_raw_task
    return _run_raw_task(
           ^^^^^^^^^^^^^^
  File "/home/airflow/.local/lib/python3.12/site-packages/airflow/models/taskinstance.py", line 273, in _run_raw_task
    TaskInstance._execute_task_with_callbacks(
  File "/home/airflow/.local/lib/python3.12/site-packages/airflow/models/taskinstance.py", line 3158, in _execute_task_with_callbacks
    result = self._execute_task(context, task_orig)
             ^^^^^^^^^^^^^^^^^^^^^^^^^^^^^^^^^^^^^^
  File "/home/airflow/.local/lib/python3.12/site-packages/airflow/models/taskinstance.py", line 3182, in _execute_task
    return _execute_task(self, context, task_orig)
           ^^^^^^^^^^^^^^^^^^^^^^^^^^^^^^^^^^^^^^^
  File "/home/airflow/.local/lib/python3.12/site-packages/airflow/models/taskinstance.py", line 767, in _execute_task
    result = _execute_callable(context=context, **execute_callable_kwargs)
             ^^^^^^^^^^^^^^^^^^^^^^^^^^^^^^^^^^^^^^^^^^^^^^^^^^^^^^^^^^^^^
  File "/home/airflow/.local/lib/python3.12/site-packages/airflow/models/taskinstance.py", line 733, in _execute_callable
    return ExecutionCallableRunner(
           ^^^^^^^^^^^^^^^^^^^^^^^^
  File "/home/airflow/.local/lib/python3.12/site-packages/airflow/utils/operator_helpers.py", line 252, in run
    return self.func(*args, **kwargs)
           ^^^^^^^^^^^^^^^^^^^^^^^^^^
  File "/home/airflow/.local/lib/python3.12/site-packages/airflow/models/baseoperator.py", line 406, in wrapper
    return func(self, *args, **kwargs)
           ^^^^^^^^^^^^^^^^^^^^^^^^^^^
  File "/home/airflow/.local/lib/python3.12/site-packages/airflow/operators/python.py", line 238, in execute
    return_value = self.execute_callable()
                   ^^^^^^^^^^^^^^^^^^^^^^^
  File "/home/airflow/.local/lib/python3.12/site-packages/airflow/operators/python.py", line 256, in execute_callable
    return runner.run(*self.op_args, **self.op_kwargs)
           ^^^^^^^^^^^^^^^^^^^^^^^^^^^^^^^^^^^^^^^^^^^
  File "/home/airflow/.local/lib/python3.12/site-packages/airflow/utils/operator_helpers.py", line 252, in run
    return self.func(*args, **kwargs)
           ^^^^^^^^^^^^^^^^^^^^^^^^^^
  File "/opt/airflow/dags/pipeline.py", line 44, in load_data
    df = pd.read_csv(data_path)
         ^^^^^^^^^^^^^^^^^^^^^^
  File "/home/airflow/.local/lib/python3.12/site-packages/pandas/io/parsers/readers.py", line 1026, in read_csv
    return _read(filepath_or_buffer, kwds)
           ^^^^^^^^^^^^^^^^^^^^^^^^^^^^^^^
  File "/home/airflow/.local/lib/python3.12/site-packages/pandas/io/parsers/readers.py", line 620, in _read
    parser = TextFileReader(filepath_or_buffer, **kwds)
             ^^^^^^^^^^^^^^^^^^^^^^^^^^^^^^^^^^^^^^^^^^
  File "/home/airflow/.local/lib/python3.12/site-packages/pandas/io/parsers/readers.py", line 1620, in __init__
    self._engine = self._make_engine(f, self.engine)
                   ^^^^^^^^^^^^^^^^^^^^^^^^^^^^^^^^^
  File "/home/airflow/.local/lib/python3.12/site-packages/pandas/io/parsers/readers.py", line 1880, in _make_engine
    self.handles = get_handle(
                   ^^^^^^^^^^^
  File "/home/airflow/.local/lib/python3.12/site-packages/pandas/io/common.py", line 873, in get_handle
    handle = open(
             ^^^^^
FileNotFoundError: [Errno 2] No such file or directory: 'C:/Users/LENOVO/Documents/machine_learning_engineer/DMC/practica1/dags/data/train.csv'
[2024-10-13T23:05:33.483+0000] {local_task_job_runner.py:266} INFO - Task exited with return code 1
[2024-10-13T23:05:33.542+0000] {taskinstance.py:3900} INFO - 0 downstream tasks scheduled from follow-on schedule check
[2024-10-13T23:05:33.560+0000] {local_task_job_runner.py:245} INFO - ::endgroup::
