[2024-10-13T22:46:31.888+0000] {local_task_job_runner.py:123} INFO - ::group::Pre task execution logs
[2024-10-13T22:46:31.917+0000] {taskinstance.py:2612} INFO - Dependencies all met for dep_context=non-requeueable deps ti=<TaskInstance: ml_workflow_jhayr.load_data scheduled__2024-10-12T17:00:00+00:00 [queued]>
[2024-10-13T22:46:31.934+0000] {taskinstance.py:2612} INFO - Dependencies all met for dep_context=requeueable deps ti=<TaskInstance: ml_workflow_jhayr.load_data scheduled__2024-10-12T17:00:00+00:00 [queued]>
[2024-10-13T22:46:31.935+0000] {taskinstance.py:2865} INFO - Starting attempt 1 of 2
[2024-10-13T22:46:31.963+0000] {taskinstance.py:2888} INFO - Executing <Task(PythonOperator): load_data> on 2024-10-12 17:00:00+00:00
[2024-10-13T22:46:31.985+0000] {warnings.py:112} WARNING - /home/***/.local/lib/python3.12/site-packages/***/task/task_runner/standard_task_runner.py:70: DeprecationWarning: This process (pid=268) is multi-threaded, use of fork() may lead to deadlocks in the child.
  pid = os.fork()

[2024-10-13T22:46:31.990+0000] {standard_task_runner.py:72} INFO - Started process 302 to run task
[2024-10-13T22:46:31.990+0000] {standard_task_runner.py:104} INFO - Running: ['***', 'tasks', 'run', 'ml_workflow_jhayr', 'load_data', 'scheduled__2024-10-12T17:00:00+00:00', '--job-id', '12', '--raw', '--subdir', 'DAGS_FOLDER/pipeline.py', '--cfg-path', '/tmp/tmpt719krm5']
[2024-10-13T22:46:31.993+0000] {standard_task_runner.py:105} INFO - Job 12: Subtask load_data
[2024-10-13T22:46:32.128+0000] {task_command.py:467} INFO - Running <TaskInstance: ml_workflow_jhayr.load_data scheduled__2024-10-12T17:00:00+00:00 [running]> on host 5ab3b13c1635
[2024-10-13T22:46:32.337+0000] {taskinstance.py:3131} INFO - Exporting env vars: AIRFLOW_CTX_DAG_OWNER='***' AIRFLOW_CTX_DAG_ID='ml_workflow_jhayr' AIRFLOW_CTX_TASK_ID='load_data' AIRFLOW_CTX_EXECUTION_DATE='2024-10-12T17:00:00+00:00' AIRFLOW_CTX_TRY_NUMBER='1' AIRFLOW_CTX_DAG_RUN_ID='scheduled__2024-10-12T17:00:00+00:00'
[2024-10-13T22:46:32.340+0000] {logging_mixin.py:190} INFO - Task instance is in running state
[2024-10-13T22:46:32.342+0000] {logging_mixin.py:190} INFO -  Previous state of the Task instance: queued
[2024-10-13T22:46:32.343+0000] {logging_mixin.py:190} INFO - Current task name:load_data state:running start_date:2024-10-13 22:46:31.918269+00:00
[2024-10-13T22:46:32.344+0000] {logging_mixin.py:190} INFO - Dag name:ml_workflow_jhayr and current dag run status:running
[2024-10-13T22:46:32.345+0000] {taskinstance.py:731} INFO - ::endgroup::
[2024-10-13T22:46:32.347+0000] {taskinstance.py:3310} ERROR - Task failed with exception
Traceback (most recent call last):
  File "/home/airflow/.local/lib/python3.12/site-packages/airflow/models/taskinstance.py", line 767, in _execute_task
    result = _execute_callable(context=context, **execute_callable_kwargs)
             ^^^^^^^^^^^^^^^^^^^^^^^^^^^^^^^^^^^^^^^^^^^^^^^^^^^^^^^^^^^^^
  File "/home/airflow/.local/lib/python3.12/site-packages/airflow/models/taskinstance.py", line 733, in _execute_callable
    return ExecutionCallableRunner(
           ^^^^^^^^^^^^^^^^^^^^^^^^
  File "/home/airflow/.local/lib/python3.12/site-packages/airflow/utils/operator_helpers.py", line 252, in run
    return self.func(*args, **kwargs)
           ^^^^^^^^^^^^^^^^^^^^^^^^^^
  File "/home/airflow/.local/lib/python3.12/site-packages/airflow/models/baseoperator.py", line 406, in wrapper
    return func(self, *args, **kwargs)
           ^^^^^^^^^^^^^^^^^^^^^^^^^^^
  File "/home/airflow/.local/lib/python3.12/site-packages/airflow/operators/python.py", line 238, in execute
    return_value = self.execute_callable()
                   ^^^^^^^^^^^^^^^^^^^^^^^
  File "/home/airflow/.local/lib/python3.12/site-packages/airflow/operators/python.py", line 256, in execute_callable
    return runner.run(*self.op_args, **self.op_kwargs)
           ^^^^^^^^^^^^^^^^^^^^^^^^^^^^^^^^^^^^^^^^^^^
  File "/home/airflow/.local/lib/python3.12/site-packages/airflow/utils/operator_helpers.py", line 252, in run
    return self.func(*args, **kwargs)
           ^^^^^^^^^^^^^^^^^^^^^^^^^^
  File "/opt/airflow/dags/pipeline.py", line 44, in load_data
    df = pd.read_cvs(data_path)
         ^^^^^^^^^^^
AttributeError: module 'pandas' has no attribute 'read_cvs'. Did you mean: 'read_csv'?
[2024-10-13T22:46:32.386+0000] {logging_mixin.py:190} INFO - Task instance in failure state
[2024-10-13T22:46:32.391+0000] {logging_mixin.py:190} INFO - Task start:2024-10-13 22:46:31.918269+00:00 end:2024-10-13 22:46:32.385634+00:00 duration:0.467365
[2024-10-13T22:46:32.392+0000] {logging_mixin.py:190} INFO - Task:<Task(PythonOperator): load_data> dag:<DAG: ml_workflow_jhayr> dagrun:<DagRun ml_workflow_jhayr @ 2024-10-12 17:00:00+00:00: scheduled__2024-10-12T17:00:00+00:00, state:running, queued_at: 2024-10-13 22:46:24.404831+00:00. externally triggered: False>
[2024-10-13T22:46:32.393+0000] {logging_mixin.py:190} INFO - Failure caused by module 'pandas' has no attribute 'read_cvs'
[2024-10-13T22:46:32.394+0000] {taskinstance.py:1225} INFO - Marking task as UP_FOR_RETRY. dag_id=ml_workflow_jhayr, task_id=load_data, run_id=scheduled__2024-10-12T17:00:00+00:00, execution_date=20241012T170000, start_date=20241013T224631, end_date=20241013T224632
[2024-10-13T22:46:32.425+0000] {taskinstance.py:340} INFO - ::group::Post task execution logs
[2024-10-13T22:46:32.426+0000] {standard_task_runner.py:124} ERROR - Failed to execute job 12 for task load_data (module 'pandas' has no attribute 'read_cvs'; 302)
Traceback (most recent call last):
  File "/home/airflow/.local/lib/python3.12/site-packages/airflow/task/task_runner/standard_task_runner.py", line 117, in _start_by_fork
    ret = args.func(args, dag=self.dag)
          ^^^^^^^^^^^^^^^^^^^^^^^^^^^^^
  File "/home/airflow/.local/lib/python3.12/site-packages/airflow/cli/cli_config.py", line 49, in command
    return func(*args, **kwargs)
           ^^^^^^^^^^^^^^^^^^^^^
  File "/home/airflow/.local/lib/python3.12/site-packages/airflow/utils/cli.py", line 115, in wrapper
    return f(*args, **kwargs)
           ^^^^^^^^^^^^^^^^^^
  File "/home/airflow/.local/lib/python3.12/site-packages/airflow/cli/commands/task_command.py", line 483, in task_run
    task_return_code = _run_task_by_selected_method(args, _dag, ti)
                       ^^^^^^^^^^^^^^^^^^^^^^^^^^^^^^^^^^^^^^^^^^^^
  File "/home/airflow/.local/lib/python3.12/site-packages/airflow/cli/commands/task_command.py", line 256, in _run_task_by_selected_method
    return _run_raw_task(args, ti)
           ^^^^^^^^^^^^^^^^^^^^^^^
  File "/home/airflow/.local/lib/python3.12/site-packages/airflow/cli/commands/task_command.py", line 341, in _run_raw_task
    return ti._run_raw_task(
           ^^^^^^^^^^^^^^^^^
  File "/home/airflow/.local/lib/python3.12/site-packages/airflow/utils/session.py", line 97, in wrapper
    return func(*args, session=session, **kwargs)
           ^^^^^^^^^^^^^^^^^^^^^^^^^^^^^^^^^^^^^^
  File "/home/airflow/.local/lib/python3.12/site-packages/airflow/models/taskinstance.py", line 3004, in _run_raw_task
    return _run_raw_task(
           ^^^^^^^^^^^^^^
  File "/home/airflow/.local/lib/python3.12/site-packages/airflow/models/taskinstance.py", line 273, in _run_raw_task
    TaskInstance._execute_task_with_callbacks(
  File "/home/airflow/.local/lib/python3.12/site-packages/airflow/models/taskinstance.py", line 3158, in _execute_task_with_callbacks
    result = self._execute_task(context, task_orig)
             ^^^^^^^^^^^^^^^^^^^^^^^^^^^^^^^^^^^^^^
  File "/home/airflow/.local/lib/python3.12/site-packages/airflow/models/taskinstance.py", line 3182, in _execute_task
    return _execute_task(self, context, task_orig)
           ^^^^^^^^^^^^^^^^^^^^^^^^^^^^^^^^^^^^^^^
  File "/home/airflow/.local/lib/python3.12/site-packages/airflow/models/taskinstance.py", line 767, in _execute_task
    result = _execute_callable(context=context, **execute_callable_kwargs)
             ^^^^^^^^^^^^^^^^^^^^^^^^^^^^^^^^^^^^^^^^^^^^^^^^^^^^^^^^^^^^^
  File "/home/airflow/.local/lib/python3.12/site-packages/airflow/models/taskinstance.py", line 733, in _execute_callable
    return ExecutionCallableRunner(
           ^^^^^^^^^^^^^^^^^^^^^^^^
  File "/home/airflow/.local/lib/python3.12/site-packages/airflow/utils/operator_helpers.py", line 252, in run
    return self.func(*args, **kwargs)
           ^^^^^^^^^^^^^^^^^^^^^^^^^^
  File "/home/airflow/.local/lib/python3.12/site-packages/airflow/models/baseoperator.py", line 406, in wrapper
    return func(self, *args, **kwargs)
           ^^^^^^^^^^^^^^^^^^^^^^^^^^^
  File "/home/airflow/.local/lib/python3.12/site-packages/airflow/operators/python.py", line 238, in execute
    return_value = self.execute_callable()
                   ^^^^^^^^^^^^^^^^^^^^^^^
  File "/home/airflow/.local/lib/python3.12/site-packages/airflow/operators/python.py", line 256, in execute_callable
    return runner.run(*self.op_args, **self.op_kwargs)
           ^^^^^^^^^^^^^^^^^^^^^^^^^^^^^^^^^^^^^^^^^^^
  File "/home/airflow/.local/lib/python3.12/site-packages/airflow/utils/operator_helpers.py", line 252, in run
    return self.func(*args, **kwargs)
           ^^^^^^^^^^^^^^^^^^^^^^^^^^
  File "/opt/airflow/dags/pipeline.py", line 44, in load_data
    df = pd.read_cvs(data_path)
         ^^^^^^^^^^^
AttributeError: module 'pandas' has no attribute 'read_cvs'. Did you mean: 'read_csv'?
[2024-10-13T22:46:32.492+0000] {local_task_job_runner.py:266} INFO - Task exited with return code 1
[2024-10-13T22:46:32.540+0000] {taskinstance.py:3900} INFO - 0 downstream tasks scheduled from follow-on schedule check
[2024-10-13T22:46:32.543+0000] {local_task_job_runner.py:245} INFO - ::endgroup::
